Workbook

Sheet BCA-2023-2026
A1: S.No. | B1: Roll No. | C1: Reg. No | D1: Name | E1: Father's Name | F1: Mobile No. | G1: Email ID | H1: Section | I1: Group Specialization | J1: Course Changed | K1: Group | L1: Specialization | M1: 1st Sem. | N1: 2nd Sem. | O1: 3rd Sem. | P1: 4th Sem. | Q1: 5th Sem. | R1: 6th Sem. | S1: Average
A2: 1 | B2: 1323001 | C2: 23-MCM- | S2: =AVERAGE(M2:P2) -> #DIV/0!
A3: 2 | B3: 1323002 | C3: 23-MCM-001 | D3: SHELLY KAMBOJ | E3: SUNIL KAMBOJ | F3: 6398068307 | G3: Kambojshelly674@gmail.com | H3: A | J3: BCA (Data Science) | L3: BCA | M3: 6.2 | N3: RE [CUL-001] | O3: RE [BCA -308] | P3: RE [BCA - 402] | S3: =AVERAGE(M3:P3) -> 6.2
A4: 3 | B4: 1323003 | C4: 23-MCM- | L4: BCA | S4: =AVERAGE(M4:P4) -> #DIV/0!
A5: 4 | B5: 1323004 | C5: 23-MCM-002 | D5: SHASHWAT | E5: NARESH KUMAR | F5: 7015333235 | G5: gambhirshavi@gmail.con | H5: A | J5: BCA | L5: BCA | M5: 6.61 | N5: 6.23 | O5: RE [BCA -308] | P5: 6.39 | S5: =AVERAGE(M5:P5) -> 6.41
A6: 5 | B6: 1323005 | C6: 23-MCM-003 | D6: HARLEEN KAUR | E6: DAVINDER SINGH | M6: 8.77 | N6: RE [BCA-201, BCA-202, BCA-203, BHUM-013, ENE-101] | S6: =AVERAGE(M6:P6) -> 8.77
A7: 6 | B7: 1323006 | C7: 23-MCM-004 | D7: JASHANDEEP KAUR | E7: SURINDER SINGH | F7: 7027082784 | G7: Jasssandhu9402@gmail.com | H7: A | J7: BCA (Data Science) | L7: BCA | M7: 8.05 | N7: 8.45 | O7: 8.36 | P7: 7.32 | S7: =AVERAGE(M7:P7) -> 8.045
A8: 7 | B8: 1323007 | C8: 23-MCM-005 | D8: JATIN PANCHAL | E8: PARDEEP KUMAR | F8: 7027435871 | G8: jatinpanchal01235@gmail.com | H8: A | J8: BCA | L8: BCA | M8: 7.45 | N8: 8.18 | O8: 7.95 | P8: 7.55 | S8: =AVERAGE(M8:P8) -> 7.7825
A9: 8 | B9: 1323008 | C9: 23-MCM-006 | D9: PARAVDEEP KAUR | E9: SUKHWINDER SINGH | F9: 7027684989 | G9: kaurparavdeep01@gmail.com | H9: A | J9: BCA (Data Science) | L9: AI | M9: RE [BCA -102] | N9: RE [BCA-201, BCA-202, BCA-203] | O9: RE [BCA- 306,BCA -308] | P9: 6.66 | S9: =AVERAGE(M9:P9) -> 6.66
A10: 9 | B10: 1323009 | C10: 23-MCM-007 | D10: RAM | E10: ASHOK JHA | F10: 7027743511 | G10: jairam4247@gmail.com | H10: A | J10: BCA | L10: BCA | M10: 6.55 | N10: 6.84 | O10: 7.59 | P10: 6.25 | S10: =AVERAGE(M10:P10) -> 6.8075
A11: 10 | B11: 1323010 | C11: 23-MCM-008 | D11: PANKAJ BAGAULI | E11: NAVEEN CHANDRA BAGAULI | F11: 7055570167 | G11: pankajbagauli03@gmail.com | H11: A | J11: BCA (Data Science) | L11: BCA | M11: 7.91 | N11: 8.55 | O11: 7.91 | P11: 7.41 | S11: =AVERAGE(M11:P11) -> 7.945
A12: 11 | B12: 1323011 | C12: 23-MCM-009 | D12: LAKSHAY | E12: AJAY KUMAR | F12: 7056088460 | G12: lakshayjuneja003@gmail.com | H12: A | J12: BCA (AI & ML) | L12: DS | M12: 7.73 | N12: 8.59 | O12: 8.09 | P12: 7.11 | S12: =AVERAGE(M12:P12) -> 7.88
A13: 12 | B13: 1323012 | C13: 23-MCM-010 | D13: MEENAKSHI | E13: KRISHAN | F13: 7056369950 | G13: meenakshidhiman335@gmail.com | H13: A | J13: BCA | L13: BCA | M13: 8.68 | N13: 9.23 | O13: 9.5 | P13: 8.95 | S13: =AVERAGE(M13:P13) -> 9.09
A14: 13 | B14: 1323013 | C14: 23-MCM-011 | D14: SANDEEP KUMAR SAINI | E14: PURAN CHAND | M14: RLS | N14: RE [BCA-201, BCA-202, BCA-203, BHUM-013, ENE-101, BCA-204, BCA-205] | O14: 8.73 | S14: =AVERAGE(M14:P14) -> 8.73
A15: 14 | B15: 1323014 | C15: 23-MCM-012 | D15: VANSH MAINI | E15: RAJESH KUMAR | M15: RL(REGN.) | S15: =AVERAGE(M15:P15) -> #DIV/0!
A16: 15 | B16: 1323015 | C16: 23-MCM-013 | D16: DIVYANSHI | E16: SUNIL DUTT SHARMA | F16: 7206610722 | G16: ak2368307@gmail.com | H16: A | J16: BCA | L16: BCA | M16: 7.91 | N16: 8.41 | P16: 8.14 | S16: =AVERAGE(M16:P16) -> 8.1533333
A17: 16 | B17: 1323016 | C17: 23-MCM-014 | D17: KUNAL TALWAR | E17: VARINDER KUMAR | F17: 7206639042 | G17: kunaltalwar387@gmail.com | H17: A | L17: BCA | M17: 6.77 | N17: 6.95 | O17: RE [BCA- 306,BCA -308] | P17: RE [BCA -403] | S17: =AVERAGE(M17:P17) -> 6.86
A18: 17 | B18: 1323017 | C18: 23-MCM-015 | D18: ARPIT | E18: PAWAN KUMAR | F18: 8307255025 | G18: arpitbains83072@gmail.com | H18: A | J18: BCA | L18: BCA | M18: 6.07 | N18: RE [BCA-201] | O18: RE [BCA -308] | P18: RE [BCA - 401,BCA - 402] | S18: =AVERAGE(M18:P18) -> 6.07
A19: 18 | B19: 1323018 | C19: 23-MCM-016 | D19: VANSHAM DUTTA | E19: ASHWANI DUTTA | F19: 7393900039 | G19: vanshamdutta@gmail.com | H19: A | J19: BCA | L19: BCA | M19: 6.75 | N19: 6.82 | O19: RE [BCA -308] | P19: RE [BCA -403,BHUM-022] | S19: =AVERAGE(M19:P19) -> 6.785
A20: 19 | B20: 1323019 | C20: 23-MCM-017 | D20: JANVI | E20: RAJEEV SHANKAR | F20: 7404285548 | G20: janvipandey8950@gmail.com | H20: A | J20: BCA | L20: BCA | M20: 8.5 | N20: 9 | O20: 9.05 | P20: 8.82 | S20: =AVERAGE(M20:P20) -> 8.8425
A21: 20 | B21: 1323020 | C21: 23-MCM-018 | D21: HIMANSHU | E21: BALINDER SINGH | M21: RL(REGN.) | S21: =AVERAGE(M21:P21) -> #DIV/0!
A22: 21 | B22: 1323021 | C22: 23-MCM-019 | D22: NIKHIL | E22: PARMOD KUMAR | H22: A | L22: BCA | M22: BCA-101, BCA-102, BCA-103, BCA-104, BHUM-011, HSMC-051, BCA-105, BCA-106 | N22: RE [BCA-201, BCA-202, BCA-203, BHUM-013, ENE-101, BCA-204, BCA-205, BCA-206] | S22: =AVERAGE(M22:P22) -> #DIV/0!
A23: 22 | B23: 1323022 | C23: 23-MCM-020 | D23: VANSH | E23: PARDEEP | F23: 7404743742 | G23: Nainvansh748@email.com | H23: A | L23: BCA | M23: 6.91 | N23: RE [BCA-205, BCA-204, BCA-201, BCA-202, BCA-203, BCA-206] | O23: RE [BCA -308] | P23: RE [MAN-001] | S23: =AVERAGE(M23:P23) -> 6.91
A24: 23 | B24: 1323023 | C24: 23-MCM-021 | D24: JAYA SHARMA | E24: PARDEEP SHARMA | F24: 7419206501 | G24: Jiyasharma200220@gmail.com | H24: A | J24: BCA (AI & ML) | L24: BCA | M24: 8.18 | N24: 7.95 | O24: RE [BCA -308] | P24: 7.95 | S24: =AVERAGE(M24:P24) -> 8.0266667
A25: 24 | B25: 1323024 | C25: 23-MCM-000 | S25: =AVERAGE(M25:P25) -> #DIV/0!
A26: 25 | B26: 1323025 | C26: 23-MCM-022 | D26: CHAKSHIT LUTHRA | E26: SANJEEV KUMAR | F26: 7496018760 | G26: Chakshitluthra78@gmail.com | H26: A | J26: BCA | L26: BCA | M26: 6.82 | N26: 6.61 | O26: RE [BCA- 307,BCA -308] | P26: RE [BCA - 401,BCA - 402,BCA -403,BCA - 404,BHUM-022,MAN-001] | S26: =AVERAGE(M26:P26) -> 6.715
A27: 26 | B27: 1323026 | C27: 23-MCM-023 | D27: AMBER SHARMA | E27: ASHWANI KUMAR | F27: 7500139374 | G27: ambersharma681@gmail.com | H27: A | J27: BCA | L27: BCA | M27: 7.23 | N27: 7.55 | O27: 8.23 | P27: 6.68 | S27: =AVERAGE(M27:P27) -> 7.4225
A28: 27 | B28: 1323027 | C28: 23-MCM-024 | D28: SAHIL | E28: RAVINDER | F28: 9817026844 | G28: Sr0473403@gmail.com | H28: A | J28: BCA (Data Science) | L28: BCA | M28: 7.27 | N28: RLA | O28: RE [BCA -308] | P28: RLS | S28: =AVERAGE(M28:P28) -> 7.27
A29: 28 | B29: 1323028 | C29: 23-MCM-025 | D29: SHUBHAM BAKSHI | E29: DHARMINDER BAKSHI | F29: 7876863816 | G29: Shubhambakshi2005@gmail.com | H29: A | J29: BCA | L29: BCA | M29: 6.75 | N29: RE [BCA-201, BCA-206] | O29: RE [BCA -308] | P29: 5.8 | S29: =AVERAGE(M29:P29) -> 6.275
A30: 29 | B30: 1323029 | C30: 23-MCM-026 | D30: HARSHDIP SINGH | E30: RAMESH SINGH | F30: 7973957117 | G30: harshpardhan1717@gmail.com | H30: A | L30: BCA | M30: BCA-102, BCA-104, HSMC-051 | N30: RE [BCA-201, BCA-202, BCA-203] | O30: RE [BCA- 302,BCA-304,BCA- 305,BCA- 306,BCA- 307,BCA -308] | P30: RE [BCA - 401,BCA -403,BCA - 404,BCA - 405,BCA - 406,BHUM-022,BCIV-180] | S30: =AVERAGE(M30:P30) -> #DIV/0!
A31: 30 | B31: 1323030 | C31: 23-MCM-027 | D31: AKHIL KUMAR | E31: MANGAT RAM | F31: 7988539214 | G31: akhilkashyap964@gmail.com | H31: A | J31: BCA | L31: BCA | M31: RE [BCA -104] | N31: RE [BCA-201, BCA-203, BCA-206] | O31: RE [BCA -308] | P31: 7.59 | S31: =AVERAGE(M31:P31) -> 7.59
A32: 31 | B32: 1323031 | C32: 23-MCM-028 | D32: SAKSHI MEHTA | E32: SANDEEP MEHTA | F32: 7988585307 | G32: sakshimehta.010191@gmail.com | H32: A | J32: BCA | L32: BCA | M32: 9.36 | N32: 8.91 | O32: 8.95 | P32: 9.32 | S32: =AVERAGE(M32:P32) -> 9.135
A33: 32 | B33: 1323032 | C33: 23-MCM-029 | D33: MANPREET KAUR | E33: BHULLA SINGH | F33: 8053095927 | G33: manpreet85345@yahoo.com | H33: A | J33: BCA | L33: AI | M33: 7.32 | N33: RE [BCA-201, BCA-202, BCA-203] | O33: 8.36 | P33: ABSENT | S33: =AVERAGE(M33:P33) -> 7.84
A34: 33 | B34: 1323033 | C34: 23-MCM-030 | D34: VEERPARTAP SINGH | E34: SORABH KUMAR | F34: 8053211500 | G34: vpsinghmarwa@gmail.com | H34: A | J34: BCA | L34: BCA | M34: 7.32 | N34: RE [BCA-201, BCA-202, BCA-203, BHUM-013, ENE-101, BCA-204, BCA-205] | O34: RE [BCA -308] | P34: RE [MAN-001] | S34: =AVERAGE(M34:P34) -> 7.32
A35: 34 | B35: 1323034 | C35: 23-MCM-031 | D35: DIVYA SHARMA | E35: MOHINDER PAL | F35: 8053841041 | G35: divyaasharma2006@gmail.com | H35: A | J35: BCA (Data Science) | L35: BCA | M35: 8.55 | N35: 8.41 | O35: 8.27 | P35: 8.95 | S35: =AVERAGE(M35:P35) -> 8.545
A36: 35 | B36: 1323035 | C36: 23-MCM-032 | L36: BCA | S36: =AVERAGE(M36:P36) -> #DIV/0!
A37: 36 | B37: 1323036 | C37: 23-MCM-033 | D37: RASHI SHARMA | E37: RAVINDER SHARMA | F37: 8168091086 | G37: Rasshisharma200@gmail.com | H37: A | J37: BCA | L37: BCA | M37: 7.64 | N37: 7.93 | O37: 8.09 | P37: 8 | S37: =AVERAGE(M37:P37) -> 7.915
A38: 37 | B38: 1323037 | C38: 23-MCM-034 | D38: PALAKPREET KAUR | E38: GURJIT SINGH | F38: 8168105044 | G38: multanipalak01@gmail.com | H38: A | J38: BCA | L38: AI | M38: BCA-101, BCA-102, BCA-103, BCA-104, BCA-105, BCA-106 | N38: RLA | O38: RE [BCA- 306,BCA- 307,BCA -308] | P38: 7.36 | S38: =AVERAGE(M38:P38) -> 7.36
A39: 38 | B39: 1323038 | C39: 23-MCM-035 | D39: MOHIT | E39: RAKESH KUMAR | F39: 8168199269 | G39: aggarwalmohit171@gmail.com | H39: A | J39: BCA (AI & ML) | L39: BCA | M39: 6.09 | N39: 6.09 | O39: RE [BCA- 307,BCA -308] | P39: 6.3 | S39: =AVERAGE(M39:P39) -> 6.16
A40: 39 | B40: 1323039 | C40: 23-MCM-036 | D40: CHAVI DHIMAN | E40: SANJEEV KUMAR | F40: 8168760188 | G40: chavidhiman065@gmail.com | H40: A | J40: BCA | L40: BCA | M40: 7.45 | N40: 7.25 | O40: 7.64 | P40: 8.23 | S40: =AVERAGE(M40:P40) -> 7.6425
...

Sheet V-Lookup
B3: PROGRESS SHEET | J3: Update Module
B5: Student's Name | C5: =VLOOKUP($G$6,'BCA-2023-2026'!$B$2:$R$631,3,FALSE) -> PRATIPAL KUMAR SINGH | G5: Roll No. | J5: Roll_No. | K5: 1323607
B6: Father's Name | C6: =VLOOKUP($G$6,'BCA-2023-2026'!$B$2:$R$631,4,FALSE) -> SAWDHAN SINGH | G6: 1323607 | J6: =VLOOKUP($K$5,'BCA-2023-2026'!$B$2:$R$631,3,FALSE) -> PRATIPAL KUMAR SINGH
B7: Registration No. | C7: =VLOOKUP($G$6,'BCA-2023-2026'!$B$2:$R$631,2,FALSE) -> 23-MCM-576 | E7: Section. | F7: =VLOOKUP($G$6,'BCA-2023-2026'!$B$2:$R$631,7,FALSE) -> G | G7: Specail. | H7: =VLOOKUP($G$6,'BCA-2023-2026'!$B$2:$R$631,9,FALSE) -> BCA (Data Science) | J7: Sem. 1
B8: Sem. 1 | C8: =VLOOKUP($G$6,'BCA-2023-2026'!$B$2:$R$631,12,FALSE) -> 7 | J8: Sem. 2
B9: Sem. 2 | C9: =VLOOKUP($G$6,'BCA-2023-2026'!$B$2:$R$631,13,FALSE) -> 8.05 | J9: Sem. 3
B10: Sem. 3 | C10: =VLOOKUP($G$6,'BCA-2023-2026'!$B$2:$R$631,14,FALSE) -> 9.05 | J10: Sem. 4
B11: Sem. 4 | C11: =VLOOKUP($G$6,'BCA-2023-2026'!$B$2:$R$631,15,FALSE) -> 7.36 | J11: Sem. 5
B12: Sem. 5 | C12: =VLOOKUP($G$6,'BCA-2023-2026'!$B$2:$R$631,16,FALSE) -> 0 | J12: Sem. 6
B13: Sem. 6 | C13: =VLOOKUP($G$6,'BCA-2023-2026'!$B$2:$R$631,17,FALSE) -> 0
B14: Average | C14: =AVERAGE(C8:H11) -> 7.865

Sheet BCA-2023-UPDATE
A1: S.No. | B1: Roll No. | C1: Reg. No | D1: Name | E1: Father's Name | F1: Mobile No. | G1: Email ID | H1: Section | I1: Group Specialization | J1: Course Changed | K1: Group | L1: Specialization | M1: 1st Sem. | N1: 2nd Sem. | O1: 3rd Sem. | P1: 4th Sem. | Q1: 5th Sem. | R1: 6th Sem. | S1: Average
A2: 1 | B2: 1323001 | C2: 23-MCM- | S2: =AVERAGE(M2:P2) -> #DIV/0!
A3: 2 | B3: 1323002 | C3: 23-MCM-001 | D3: SHELLY KAMBOJ | E3: SUNIL KAMBOJ | F3: 6398068307 | G3: Kambojshelly674@gmail.com | H3: A | J3: BCA (Data Science) | L3: BCA | M3: 6.2 | N3: RE [CUL-001] | O3: RE [BCA -308] | P3: RE [BCA - 402] | S3: =AVERAGE(M3:P3) -> 6.2
A4: 3 | B4: 1323003 | C4: 23-MCM- | L4: BCA | S4: =AVERAGE(M4:P4) -> #DIV/0!
A5: 4 | B5: 1323004 | C5: 23-MCM-002 | D5: SHASHWAT | E5: NARESH KUMAR | F5: 7015333235 | G5: gambhirshavi@gmail.con | H5: A | J5: BCA | L5: BCA | M5: 6.61 | N5: 6.23 | O5: RE [BCA -308] | P5: 6.39 | S5: =AVERAGE(M5:P5) -> 6.41
A6: 5 | B6: 1323005 | C6: 23-MCM-003 | D6: HARLEEN KAUR | E6: DAVINDER SINGH | M6: 8.77 | N6: RE [BCA-201, BCA-202, BCA-203, BHUM-013, ENE-101] | S6: =AVERAGE(M6:P6) -> 8.77
A7: 6 | B7: 1323006 | C7: 23-MCM-004 | D7: JASHANDEEP KAUR | E7: SURINDER SINGH | F7: 7027082784 | G7: Jasssandhu9402@gmail.com | H7: A | J7: BCA (Data Science) | L7: BCA | M7: 8.05 | N7: 8.45 | O7: 8.36 | P7: 7.32 | S7: =AVERAGE(M7:P7) -> 8.045
A8: 7 | B8: 1323007 | C8: 23-MCM-005 | D8: JATIN PANCHAL | E8: PARDEEP KUMAR | F8: 7027435871 | G8: jatinpanchal01235@gmail.com | H8: A | J8: BCA | L8: BCA | M8: 7.45 | N8: 8.18 | O8: 7.95 | P8: 7.55 | S8: =AVERAGE(M8:P8) -> 7.7825
A9: 8 | B9: 1323008 | C9: 23-MCM-006 | D9: PARAVDEEP KAUR | E9: SUKHWINDER SINGH | F9: 7027684989 | G9: kaurparavdeep01@gmail.com | H9: A | J9: BCA (Data Science) | L9: AI | M9: RE [BCA -102] | N9: RE [BCA-201, BCA-202, BCA-203] | O9: RE [BCA- 306,BCA -308] | P9: 6.66 | S9: =AVERAGE(M9:P9) -> 6.66
A10: 9 | B10: 1323009 | C10: 23-MCM-007 | D10: RAM | E10: ASHOK JHA | F10: 7027743511 | G10: jairam4247@gmail.com | H10: A | J10: BCA | L10: BCA | M10: 6.55 | N10: 6.84 | O10: 7.59 | P10: 6.25 | S10: =AVERAGE(M10:P10) -> 6.8075
A11: 10 | B11: 1323010 | C11: 23-MCM-008 | D11: PANKAJ BAGAULI | E11: NAVEEN CHANDRA BAGAULI | F11: 7055570167 | G11: pankajbagauli03@gmail.com | H11: A | J11: BCA (Data Science) | L11: BCA | M11: 7.91 | N11: 8.55 | O11: 7.91 | P11: 7.41 | S11: =AVERAGE(M11:P11) -> 7.945
A12: 11 | B12: 1323011 | C12: 23-MCM-009 | D12: LAKSHAY | E12: AJAY KUMAR | F12: 7056088460 | G12: lakshayjuneja003@gmail.com | H12: A | J12: BCA (AI & ML) | L12: DS | M12: 7.73 | N12: 8.59 | O12: 8.09 | P12: 7.11 | S12: =AVERAGE(M12:P12) -> 7.88
A13: 12 | B13: 1323012 | C13: 23-MCM-010 | D13: MEENAKSHI | E13: KRISHAN | F13: 7056369950 | G13: meenakshidhiman335@gmail.com | H13: A | J13: BCA | L13: BCA | M13: 8.68 | N13: 9.23 | O13: 9.5 | P13: 8.95 | S13: =AVERAGE(M13:P13) -> 9.09
A14: 13 | B14: 1323013 | C14: 23-MCM-011 | D14: SANDEEP KUMAR SAINI | E14: PURAN CHAND | M14: RLS | N14: RE [BCA-201, BCA-202, BCA-203, BHUM-013, ENE-101, BCA-204, BCA-205] | O14: 8.73 | S14: =AVERAGE(M14:P14) -> 8.73
A15: 14 | B15: 1323014 | C15: 23-MCM-012 | D15: VANSH MAINI | E15: RAJESH KUMAR | M15: RL(REGN.) | S15: =AVERAGE(M15:P15) -> #DIV/0!
A16: 15 | B16: 1323015 | C16: 23-MCM-013 | D16: DIVYANSHI | E16: SUNIL DUTT SHARMA | F16: 7206610722 | G16: ak2368307@gmail.com | H16: A | J16: BCA | L16: BCA | M16: 7.91 | N16: 8.41 | P16: 8.14 | S16: =AVERAGE(M16:P16) -> 8.1533333
A17: 16 | B17: 1323016 | C17: 23-MCM-014 | D17: KUNAL TALWAR | E17: VARINDER KUMAR | F17: 7206639042 | G17: kunaltalwar387@gmail.com | H17: A | L17: BCA | M17: 6.77 | N17: 6.95 | O17: RE [BCA- 306,BCA -308] | P17: RE [BCA -403] | S17: =AVERAGE(M17:P17) -> 6.86
A18: 17 | B18: 1323017 | C18: 23-MCM-015 | D18: ARPIT | E18: PAWAN KUMAR | F18: 8307255025 | G18: arpitbains83072@gmail.com | H18: A | J18: BCA | L18: BCA | M18: 6.07 | N18: RE [BCA-201] | O18: RE [BCA -308] | P18: RE [BCA - 401,BCA - 402] | S18: =AVERAGE(M18:P18) -> 6.07
A19: 18 | B19: 1323018 | C19: 23-MCM-016 | D19: VANSHAM DUTTA | E19: ASHWANI DUTTA | F19: 7393900039 | G19: vanshamdutta@gmail.com | H19: A | J19: BCA | L19: BCA | M19: 6.75 | N19: 6.82 | O19: RE [BCA -308] | P19: RE [BCA -403,BHUM-022] | S19: =AVERAGE(M19:P19) -> 6.785
A20: 19 | B20: 1323019 | C20: 23-MCM-017 | D20: JANVI | E20: RAJEEV SHANKAR | F20: 7404285548 | G20: janvipandey8950@gmail.com | H20: A | J20: BCA | L20: BCA | M20: 8.5 | N20: 9 | O20: 9.05 | P20: 8.82 | S20: =AVERAGE(M20:P20) -> 8.8425
A21: 20 | B21: 1323020 | C21: 23-MCM-018 | D21: HIMANSHU | E21: BALINDER SINGH | M21: RL(REGN.) | S21: =AVERAGE(M21:P21) -> #DIV/0!
A22: 21 | B22: 1323021 | C22: 23-MCM-019 | D22: NIKHIL | E22: PARMOD KUMAR | H22: A | L22: BCA | M22: BCA-101, BCA-102, BCA-103, BCA-104, BHUM-011, HSMC-051, BCA-105, BCA-106 | N22: RE [BCA-201, BCA-202, BCA-203, BHUM-013, ENE-101, BCA-204, BCA-205, BCA-206] | S22: =AVERAGE(M22:P22) -> #DIV/0!
A23: 22 | B23: 1323022 | C23: 23-MCM-020 | D23: VANSH | E23: PARDEEP | F23: 7404743742 | G23: Nainvansh748@email.com | H23: A | L23: BCA | M23: 6.91 | N23: RE [BCA-205, BCA-204, BCA-201, BCA-202, BCA-203, BCA-206] | O23: RE [BCA -308] | P23: RE [MAN-001] | S23: =AVERAGE(M23:P23) -> 6.91
A24: 23 | B24: 1323023 | C24: 23-MCM-021 | D24: JAYA SHARMA | E24: PARDEEP SHARMA | F24: 7419206501 | G24: Jiyasharma200220@gmail.com | H24: A | J24: BCA (AI & ML) | L24: BCA | M24: 8.18 | N24: 7.95 | O24: RE [BCA -308] | P24: 7.95 | S24: =AVERAGE(M24:P24) -> 8.0266667
A25: 24 | B25: 1323024 | C25: 23-MCM-000 | S25: =AVERAGE(M25:P25) -> #DIV/0!
A26: 25 | B26: 1323025 | C26: 23-MCM-022 | D26: CHAKSHIT LUTHRA | E26: SANJEEV KUMAR | F26: 7496018760 | G26: Chakshitluthra78@gmail.com | H26: A | J26: BCA | L26: BCA | M26: 6.82 | N26: 6.61 | O26: RE [BCA- 307,BCA -308] | P26: RE [BCA - 401,BCA - 402,BCA -403,BCA - 404,BHUM-022,MAN-001] | S26: =AVERAGE(M26:P26) -> 6.715
A27: 26 | B27: 1323026 | C27: 23-MCM-023 | D27: AMBER SHARMA | E27: ASHWANI KUMAR | F27: 7500139374 | G27: ambersharma681@gmail.com | H27: A | J27: BCA | L27: BCA | M27: 7.23 | N27: 7.55 | O27: 8.23 | P27: 6.68 | S27: =AVERAGE(M27:P27) -> 7.4225
A28: 27 | B28: 1323027 | C28: 23-MCM-024 | D28: SAHIL | E28: RAVINDER | F28: 9817026844 | G28: Sr0473403@gmail.com | H28: A | J28: BCA (Data Science) | L28: BCA | M28: 7.27 | N28: RLA | O28: RE [BCA -308] | P28: RLS | S28: =AVERAGE(M28:P28) -> 7.27
A29: 28 | B29: 1323028 | C29: 23-MCM-025 | D29: SHUBHAM BAKSHI | E29: DHARMINDER BAKSHI | F29: 7876863816 | G29: Shubhambakshi2005@gmail.com | H29: A | J29: BCA | L29: BCA | M29: 6.75 | N29: RE [BCA-201, BCA-206] | O29: RE [BCA -308] | P29: 5.8 | S29: =AVERAGE(M29:P29) -> 6.275
A30: 29 | B30: 1323029 | C30: 23-MCM-026 | D30: HARSHDIP SINGH | E30: RAMESH SINGH | F30: 7973957117 | G30: harshpardhan1717@gmail.com | H30: A | L30: BCA | M30: BCA-102, BCA-104, HSMC-051 | N30: RE [BCA-201, BCA-202, BCA-203] | O30: RE [BCA- 302,BCA-304,BCA- 305,BCA- 306,BCA- 307,BCA -308] | P30: RE [BCA - 401,BCA -403,BCA - 404,BCA - 405,BCA - 406,BHUM-022,BCIV-180] | S30: =AVERAGE(M30:P30) -> #DIV/0!
A31: 30 | B31: 1323030 | C31: 23-MCM-027 | D31: AKHIL KUMAR | E31: MANGAT RAM | F31: 7988539214 | G31: akhilkashyap964@gmail.com | H31: A | J31: BCA | L31: BCA | M31: RE [BCA -104] | N31: RE [BCA-201, BCA-203, BCA-206] | O31: RE [BCA -308] | P31: 7.59 | S31: =AVERAGE(M31:P31) -> 7.59
A32: 31 | B32: 1323031 | C32: 23-MCM-028 | D32: SAKSHI MEHTA | E32: SANDEEP MEHTA | F32: 7988585307 | G32: sakshimehta.010191@gmail.com | H32: A | J32: BCA | L32: BCA | M32: 9.36 | N32: 8.91 | O32: 8.95 | P32: 9.32 | S32: =AVERAGE(M32:P32) -> 9.135
A33: 32 | B33: 1323032 | C33: 23-MCM-029 | D33: MANPREET KAUR | E33: BHULLA SINGH | F33: 8053095927 | G33: manpreet85345@yahoo.com | H33: A | J33: BCA | L33: AI | M33: 7.32 | N33: RE [BCA-201, BCA-202, BCA-203] | O33: 8.36 | P33: ABSENT | S33: =AVERAGE(M33:P33) -> 7.84
A34: 33 | B34: 1323033 | C34: 23-MCM-030 | D34: VEERPARTAP SINGH | E34: SORABH KUMAR | F34: 8053211500 | G34: vpsinghmarwa@gmail.com | H34: A | J34: BCA | L34: BCA | M34: 7.32 | N34: RE [BCA-201, BCA-202, BCA-203, BHUM-013, ENE-101, BCA-204, BCA-205] | O34: RE [BCA -308] | P34: RE [MAN-001] | S34: =AVERAGE(M34:P34) -> 7.32
A35: 34 | B35: 1323034 | C35: 23-MCM-031 | D35: DIVYA SHARMA | E35: MOHINDER PAL | F35: 8053841041 | G35: divyaasharma2006@gmail.com | H35: A | J35: BCA (Data Science) | L35: BCA | M35: 8.55 | N35: 8.41 | O35: 8.27 | P35: 8.95 | S35: =AVERAGE(M35:P35) -> 8.545
A36: 35 | B36: 1323035 | C36: 23-MCM-032 | L36: BCA | S36: =AVERAGE(M36:P36) -> #DIV/0!
A37: 36 | B37: 1323036 | C37: 23-MCM-033 | D37: RASHI SHARMA | E37: RAVINDER SHARMA | F37: 8168091086 | G37: Rasshisharma200@gmail.com | H37: A | J37: BCA | L37: BCA | M37: 7.64 | N37: 7.93 | O37: 8.09 | P37: 8 | S37: =AVERAGE(M37:P37) -> 7.915
A38: 37 | B38: 1323037 | C38: 23-MCM-034 | D38: PALAKPREET KAUR | E38: GURJIT SINGH | F38: 8168105044 | G38: multanipalak01@gmail.com | H38: A | J38: BCA | L38: AI | M38: BCA-101, BCA-102, BCA-103, BCA-104, BCA-105, BCA-106 | N38: RLA | O38: RE [BCA- 306,BCA- 307,BCA -308] | P38: 7.36 | S38: =AVERAGE(M38:P38) -> 7.36
A39: 38 | B39: 1323038 | C39: 23-MCM-035 | D39: MOHIT | E39: RAKESH KUMAR | F39: 8168199269 | G39: aggarwalmohit171@gmail.com | H39: A | J39: BCA (AI & ML) | L39: BCA | M39: 6.09 | N39: 6.09 | O39: RE [BCA- 307,BCA -308] | P39: 6.3 | S39: =AVERAGE(M39:P39) -> 6.16
A40: 39 | B40: 1323039 | C40: 23-MCM-036 | D40: CHAVI DHIMAN | E40: SANJEEV KUMAR | F40: 8168760188 | G40: chavidhiman065@gmail.com | H40: A | J40: BCA | L40: BCA | M40: 7.45 | N40: 7.25 | O40: 7.64 | P40: 8.23 | S40: =AVERAGE(M40:P40) -> 7.6425
...

Sheet TOP Student
A1: 1323132 | B1: 23-MCM-125 | C1: TANISHA SAINI | D1: DHARMENDER SINGH | E1: 8813082298 | F1: sainitanisha223@gmail.com | G1: B | H1: =VLOOKUP($A1,'BCA-2023-2026'!$B$2:$S$641,18,FALSE) -> 9.5225
A2: 1323185 | B2: 23-MCM-176 | C2: HIMANI KHURANA | D2: YOGESH KHURANA | E2: 8295537457 | F2: himanikhurana157@gmail.com | G2: C | H2: =VLOOKUP($A2,'BCA-2023-2026'!$B$2:$S$641,18,FALSE) -> 9.455
A3: 1323272 | B3: 23-MCM-263 | C3: ISHA | D3: NARESH KUMAR | E3: 9518694402 | F3: Isha452006@gmail.com | G3: D | H3: =VLOOKUP($A3,'BCA-2023-2026'!$B$2:$S$641,18,FALSE) -> 9.3975
A4: 1323090 | B4: 23-MCM-083 | C4: RUCHI | D4: TARSEM KUMAR | E4: 9416291170 | F4: sonidevi23446@gmail.com | G4: B | H4: =VLOOKUP($A4,'BCA-2023-2026'!$B$2:$S$641,18,FALSE) -> 9.24
A5: 1323044 | B5: 23-MCM-040 | C5: SHIMALI | D5: SAKOOR MOHD | E5: 8278476658 | F5: shimali2062dav@gmail.com | G5: A | H5: =VLOOKUP($A5,'BCA-2023-2026'!$B$2:$S$641,18,FALSE) -> 9.2175
A6: 1323584 | B6: 23-MCM-554 | C6: DIVYANSH SHARMA | D6: AMAN SHARMA | E6: 9350452011 | F6: divyanshsharma01092005@gmail.c | G6: A | H6: =VLOOKUP($A6,'BCA-2023-2026'!$B$2:$S$641,18,FALSE) -> 9.215
A7: 1323262 | B7: 23-MCM-253 | C7: MANYA SHARMA | D7: RAKESH KUMAR | E7: 9350441656 | F7: manyaradhesharma0410@gmail.com | G7: D | H7: =VLOOKUP($A7,'BCA-2023-2026'!$B$2:$S$641,18,FALSE) -> 9.1925
A8: 1323153 | B8: 23-MCM-146 | C8: KAMAL PREET KAUR | D8: GURDEEP SINGH | H8: =VLOOKUP($A8,'BCA-2023-2026'!$B$2:$S$641,18,FALSE) -> 9.14
A9: 1323031 | B9: 23-MCM-028 | C9: SAKSHI MEHTA | D9: SANDEEP MEHTA | E9: 7988585307 | F9: sakshimehta.010191@gmail.com | G9: A | H9: =VLOOKUP($A9,'BCA-2023-2026'!$B$2:$S$641,18,FALSE) -> 9.135
A10: 1323193 | B10: 23-MCM-184 | C10: CHIRAG | D10: HARISH KUMAR | E10: 8607129425 | F10: chirag9111vansh@gmail.com | G10: C | H10: =VLOOKUP($A10,'BCA-2023-2026'!$B$2:$S$641,18,FALSE) -> 9.1275
A11: 1323213 | B11: 23-MCM-204 | C11: VISHU | D11: RISHI PAL | E11: 9350243679 | F11: vishusangu643@gmail.com | G11: C | H11: =VLOOKUP($A11,'BCA-2023-2026'!$B$2:$S$641,18,FALSE) -> 9.115
A12: 1323113 | B12: 23-MCM-106 | C12: ANISH GARG | D12: NAVEEN KUMAR | E12: 9416466539 | F12: anishgargg@gmail.com | G12: B | H12: =VLOOKUP($A12,'BCA-2023-2026'!$B$2:$S$641,18,FALSE) -> 9.1125
A13: 1323130 | B13: 23-MCM-123 | C13: KOMAL | D13: SANJEEV KUMAR | E13: 8295770509 | F13: sainikomal24122004@gmail.com | G13: B | H13: =VLOOKUP($A13,'BCA-2023-2026'!$B$2:$S$641,18,FALSE) -> 9.1025
A14: 1323012 | B14: 23-MCM-010 | C14: MEENAKSHI | D14: KRISHAN | E14: 7056369950 | F14: meenakshidhiman335@gmail.com | G14: A | H14: =VLOOKUP($A14,'BCA-2023-2026'!$B$2:$S$641,18,FALSE) -> 9.09
A15: 1323192 | B15: 23-MCM-183 | C15: POORVA | D15: DEEPAK BANSAL | E15: 8607122807 | F15: Poorvabansal321@gmail.com | G15: C | H15: =VLOOKUP($A15,'BCA-2023-2026'!$B$2:$S$641,18,FALSE) -> 9.09
A16: 1323172 | B16: 23-MCM-164 | C16: MEHAK RANI | D16: RAVINDER KUMAR | E16: 7496851238 | F16: mehakkeshav379@gmail.com | G16: C | H16: =VLOOKUP($A16,'BCA-2023-2026'!$B$2:$S$641,18,FALSE) -> 9.08
A17: 1323446 | B17: 23-MCM-425 | C17: ABHISHEK SINGH | D17: JAY PRAKASH SINGH | E17: 8708547161 | F17: abhishekkumar937287@gmail.com | G17: F | H17: =VLOOKUP($A17,'BCA-2023-2026'!$B$2:$S$641,18,FALSE) -> 9.0633333
A18: 1323051 | B18: 23-MCM-047 | C18: TANNU | D18: SALINDER | E18: 8307749948 | F18: salindersingh5657@gmail.com | G18: A | H18: =VLOOKUP($A18,'BCA-2023-2026'!$B$2:$S$641,18,FALSE) -> 9.01
A19: 1323259 | B19: 23-MCM-250 | C19: NANCY | D19: JASBIR SINGH | E19: 7988486930 | F19: mornancy004@gmail.com | G19: D | H19: =VLOOKUP($A19,'BCA-2023-2026'!$B$2:$S$641,18,FALSE) -> 8.9875
A20: 1323114 | B20: 23-MCM-107 | C20: POOJA NAGPAL | D20: HARISH KUMAR | E20: 9896088313 | F20: radheyshree098@gmail.com | G20: B | H20: =VLOOKUP($A20,'BCA-2023-2026'!$B$2:$S$641,18,FALSE) -> 8.9775
... A29: 1323143 | B29: 23-MCM-136 | C29: LAVEENA PAHUJA | D29: RAVI PAHUJA | E29: 8278112112 | F29: pahujaliza@gmail.com | G29: B | H29: =VLOOKUP($A29,'BCA-2023-2026'!$B$2:$S$641,18,FALSE) -> 8.8175
A30: 1323005 | B30: 23-MCM-003 | C30: HARLEEN KAUR | D30: DAVINDER SINGH | H30: =VLOOKUP($A30,'BCA-2023-2026'!$B$2:$S$641,18,FALSE) -> 8.77
A31: 1323065 | B31: 23-MCM-060 | C31: SHREYA GUPTA | D31: SUMIT GUPTA | E31: 8950548142 | F31: shreyagupta17504@gmail.com | G31: A | H31: =VLOOKUP($A31,'BCA-2023-2026'!$B$2:$S$641,18,FALSE) -> 8.76
A32: 1323195 | B32: 23-MCM-186 | C32: PAYAL | D32: SATISH KUMAR | E32: 8684075586 | F32: payalsaini6253@gmail.com | G32: C | H32: =VLOOKUP($A32,'BCA-2023-2026'!$B$2:$S$641,18,FALSE) -> 8.74
A33: 1323183 | B33: 23-MCM-174 | C33: TARANJEET KAUR | D33: GURDEEP SINGH | E33: 8295056852 | F33: Kaurtaranjeet358@gmail.com | G33: C | H33: =VLOOKUP($A33,'BCA-2023-2026'!$B$2:$S$641,18,FALSE) -> 8.7375
A34: 1323013 | B34: 23-MCM-011 | C34: SANDEEP KUMAR SAINI | D34: PURAN CHAND | H34: =VLOOKUP($A34,'BCA-2023-2026'!$B$2:$S$641,18,FALSE) -> 8.73
A35: 1323188 | B35: 23-MCM-179 | C35: ANSHIKA | D35: DAVINDER NATH | E35: 8307935954 | F35: anshikav726@gmail.com | G35: C | H35: =VLOOKUP($A35,'BCA-2023-2026'!$B$2:$S$641,18,FALSE) -> 8.7025
A36: 1323377 | B36: 23-MCM-359 | C36: MUSKAN KUMARI | D36: JITENDRA KUMAR | E36: 7827476472 | F36: muskanjitendra9@gmail.com | G36: E | H36: =VLOOKUP($A36,'BCA-2023-2026'!$B$2:$S$641,18,FALSE) -> 8.6966667
A37: 1323566 | B37: 23-MCM-539 | C37: ROHAN RAJ | D37: HEMANT KUMAR SINHA | E37: 9835819778 | F37: rohanraj28022912@gmail.com | G37: F | H37: =VLOOKUP($A37,'BCA-2023-2026'!$B$2:$S$641,18,FALSE) -> 8.65
A38: 1323182 | B38: 23-MCM-173 | C38: GARIMA | D38: ROOP SAIN | E38: 8168673148 | F38: rajputgarima058@gmail.com | G38: C | H38: =VLOOKUP($A38,'BCA-2023-2026'!$B$2:$S$641,18,FALSE) -> 8.6366667
A39: 1323079 | B39: 23-MCM-072 | C39: KHUSHBOO | D39: RAJ KUMAR | E39: 9258620589 | F39: Khushboopundir9@gmail.com | G39: A | H39: =VLOOKUP($A39,'BCA-2023-2026'!$B$2:$S$641,18,FALSE) -> 8.635
A40: 1323431 | B40: 23-MCM-413 | C40: SATYAM KUMAR | D40: SURENDRA SINGH | E40: 8789097372 | F40: satyamk5783@gmail.com | G40: F | H40: =VLOOKUP($A40,'BCA-2023-2026'!$B$2:$S$641,18,FALSE) -> 8.635
A41: 1323147 | B41: 23-MCM-140 | C41: MANPREET KAUR | D41: SAHAB SINGH | E41: 9817757835 | F41: mk1728765@gmail.com | G41: B | H41: =VLOOKUP($A41,'BCA-2023-2026'!$B$2:$S$641,18,FALSE) -> 8.6275
A42: 1323066 | B42: 23-MCM-061 | C42: NIHARIKA | D42: SANJEEV KUMAR | E42: 8950667283 | F42: rika212006@gmail.com | G42: A | H42: =VLOOKUP($A42,'BCA-2023-2026'!$B$2:$S$641,18,FALSE) -> 8.625
A43: 1323206 | B43: 23-MCM-197 | C43: MUSKAN | D43: PARVEEN | E43: 9053502469 | F43: muskanoberoi27@gmail.com | G43: C | H43: =VLOOKUP($A43,'BCA-2023-2026'!$B$2:$S$641,18,FALSE) -> 8.62
A44: 1323333 | B44: 23-MCM-000 | C44: SUMAN KUIKEL | D44: OMA NATH KUIKEL | H44: =VLOOKUP($A44,'BCA-2023-2026'!$B$2:$S$641,18,FALSE) -> 8.59
A45: 1323187 | B45: 23-MCM-178 | C45: SIDHI KANSAL | D45: SANDEEP GUPTA | E45: 8307685269 | F45: sidhikansal04@gmail.com | G45: C | H45: =VLOOKUP($A45,'BCA-2023-2026'!$B$2:$S$641,18,FALSE) -> 8.58
A46: 1323281 | B46: 23-MCM-270 | C46: KHUSHI RANA | D46: ASHOK KUMAR | E46: 9518680160 | F46: khushirana2955@gmail.com | G46: D | H46: =VLOOKUP($A46,'BCA-2023-2026'!$B$2:$S$641,18,FALSE) -> 8.57
A47: 1323052 | B47: 23-MCM-048 | C47: SHAKSHI | D47: PAWAN KUMAR | E47: 8307983683 | F47: sakshikabir0707@gmail.com | G47: A | H47: =VLOOKUP($A47,'BCA-2023-2026'!$B$2:$S$641,18,FALSE) -> 8.555
A48: 1323034 | B48: 23-MCM-031 | C48: DIVYA SHARMA | D48: MOHINDER PAL | E48: 8053841041 | F48: divyaasharma2006@gmail.com | G48: A | H48: =VLOOKUP($A48,'BCA-2023-2026'!$B$2:$S$641,18,FALSE) -> 8.545
...
